import React from 'react';

interface ErrorBoundaryState {
  hasError: boolean;
  error?: Error;
}

interface ErrorBoundaryProps {
  children: React.ReactNode;
  fallback?: React.ComponentType<{ error?: Error; retry?: () => void }>;
}

export class ErrorBoundary extends React.Component<ErrorBoundaryProps, ErrorBoundaryState> {
  constructor(props: ErrorBoundaryProps) {
    super(props);
    this.state = { hasError: false };
  }

  static getDerivedStateFromError(error: Error): ErrorBoundaryState {
    // Update state so the next render will show the fallback UI
    return { hasError: true, error };
  }

  componentDidCatch(error: Error, errorInfo: React.ErrorInfo) {
    console.error('ErrorBoundary caught an error:', error, errorInfo);
  }

  retry = () => {
    this.setState({ hasError: false, error: undefined });
  };

  render() {
    if (this.state.hasError) {
      // Custom fallback UI
      if (this.props.fallback) {
        const FallbackComponent = this.props.fallback;
        return <FallbackComponent error={this.state.error} retry={this.retry} />;
      }

      // Default fallback UI
      return (
        <div className="flex h-screen items-center justify-center bg-gray-50">
          <div className="text-center p-8 max-w-md">
            <div className="text-red-500 text-6xl mb-4">⚠️</div>
            <h2 className="text-xl font-semibold mb-2">Something went wrong</h2>
            <p className="text-gray-600 mb-4">
              {this.state.error?.message || 'An unexpected error occurred'}
            </p>
            <button
              onClick={this.retry}
              className="px-4 py-2 bg-blue-500 text-white rounded hover:bg-blue-600"
            >
              Try Again
            </button>
          </div>
        </div>
      );
    }

    return this.props.children;
  }
}

// Hook version for functional components
export const useErrorHandler = () => {
  const [error, setError] = React.useState<Error | null>(null);

  const resetError = React.useCallback(() => {
    setError(null);
  }, []);

  const handleError = React.useCallback((error: Error) => {
    console.error('useErrorHandler caught error:', error);
    setError(error);
  }, []);

  // Reset error when component unmounts
  React.useEffect(() => {
    return () => setError(null);
  }, []);

  if (error) {
    throw error; // Let ErrorBoundary handle it
  }

  return { handleError, resetError };
};
